log/output_300_2020_Attention_gpu3.log
wandb: W&B API key is configured. Use `wandb login --relogin` to force relogin
GPU device ID: 3
newdata/300_2020.npy
2024-09-06 17:23:59.765919: I tensorflow/core/platform/cpu_feature_guard.cc:193] This TensorFlow binary is optimized with oneAPI Deep Neural Network Library (oneDNN) to use the following CPU instructions in performance-critical operations:  AVX2 FMA
To enable them in other operations, rebuild TensorFlow with the appropriate compiler flags.
2024-09-06 17:24:00.791595: W tensorflow/compiler/xla/stream_executor/platform/default/dso_loader.cc:64] Could not load dynamic library 'libnvinfer.so.7'; dlerror: libnvinfer.so.7: cannot open shared object file: No such file or directory; LD_LIBRARY_PATH: /opt/cudnn/lib64:/usr/local/cuda/lib64
2024-09-06 17:24:00.791721: W tensorflow/compiler/xla/stream_executor/platform/default/dso_loader.cc:64] Could not load dynamic library 'libnvinfer_plugin.so.7'; dlerror: libnvinfer_plugin.so.7: cannot open shared object file: No such file or directory; LD_LIBRARY_PATH: /opt/cudnn/lib64:/usr/local/cuda/lib64
2024-09-06 17:24:00.791737: W tensorflow/compiler/tf2tensorrt/utils/py_utils.cc:38] TF-TRT Warning: Cannot dlopen some TensorRT libraries. If you would like to use Nvidia GPU with TensorRT, please make sure the missing libraries mentioned above are installed properly.
wandb: wandb version 0.17.9 is available!  To upgrade, please run:
wandb:  $ pip install wandb --upgrade
wandb: Tracking run with wandb version 0.12.17
wandb: Run data is saved locally in /home/qingyi/GPU20/DeepLOB/wandb/run-20240906_172355-2u8kjgut
wandb: Run `wandb offline` to turn off syncing.
wandb: Syncing run Attention
wandb: ⭐️ View project at https://wandb.ai/pqythu/futures300
wandb: 🚀 View run at https://wandb.ai/pqythu/futures300/runs/2u8kjgut
Model(
  (attn): MultiheadAttention(
    (out_proj): NonDynamicallyQuantizableLinear(in_features=10, out_features=10, bias=True)
  )
  (fc): Linear(in_features=10, out_features=5, bias=True)
)
number of parameters: 495
Training start
epoch  1 | time used:  0.65s | train_loss 1.631 | valid loss 1.822 | valid acc 0.083 | mae 1.747 | mse 3.407 | rmse 1.85 | r2 -0.01 | sharp 1.39
epoch  2 | time used:  0.18s | train_loss 1.690 | valid loss 1.822 | valid acc 0.083 | mae 1.747 | mse 3.407 | rmse 1.85 | r2 -0.01 | sharp 1.39
epoch  3 | time used:  0.18s | train_loss 1.680 | valid loss 1.863 | valid acc 0.042 | mae 1.735 | mse 4.021 | rmse 2.01 | r2 -0.19 | sharp 1.39
epoch  4 | time used:  0.18s | train_loss 1.741 | valid loss 1.543 | valid acc 0.366 | mae 2.193 | mse 8.179 | rmse 2.86 | r2 -1.43 | sharp 1.39
epoch  5 | time used:  0.17s | train_loss 1.624 | valid loss 1.540 | valid acc 0.366 | mae 2.193 | mse 8.179 | rmse 2.86 | r2 -1.43 | sharp 1.39
epoch  6 | time used:  0.17s | train_loss 1.623 | valid loss 1.540 | valid acc 0.366 | mae 2.193 | mse 8.179 | rmse 2.86 | r2 -1.43 | sharp 1.39
epoch  7 | time used:  0.18s | train_loss 1.640 | valid loss 1.822 | valid acc 0.083 | mae 1.747 | mse 3.407 | rmse 1.85 | r2 -0.01 | sharp 1.39
epoch  8 | time used:  0.17s | train_loss 1.634 | valid loss 1.540 | valid acc 0.366 | mae 2.193 | mse 8.179 | rmse 2.86 | r2 -1.43 | sharp 1.39
epoch  9 | time used:  0.16s | train_loss 1.623 | valid loss 1.540 | valid acc 0.366 | mae 2.193 | mse 8.179 | rmse 2.86 | r2 -1.43 | sharp 1.39
epoch 10 | time used:  0.16s | train_loss 1.623 | valid loss 1.540 | valid acc 0.366 | mae 2.193 | mse 8.179 | rmse 2.86 | r2 -1.43 | sharp 1.39
saving the model to ./save/2020_300/Attention/checkpoint10.pt
epoch 11 | time used:  0.17s | train_loss 1.653 | valid loss 1.822 | valid acc 0.083 | mae 1.747 | mse 3.407 | rmse 1.85 | r2 -0.01 | sharp 1.39
epoch 12 | time used:  0.16s | train_loss 1.638 | valid loss 1.462 | valid acc 0.366 | mae 2.193 | mse 8.179 | rmse 2.86 | r2 -1.43 | sharp 1.39
epoch 13 | time used:  0.16s | train_loss 1.594 | valid loss 1.540 | valid acc 0.366 | mae 2.193 | mse 8.179 | rmse 2.86 | r2 -1.43 | sharp 1.39
epoch 14 | time used:  0.16s | train_loss 1.619 | valid loss 1.540 | valid acc 0.366 | mae 2.193 | mse 8.179 | rmse 2.86 | r2 -1.43 | sharp 1.39
epoch 15 | time used:  0.17s | train_loss 1.621 | valid loss 1.540 | valid acc 0.366 | mae 2.193 | mse 8.179 | rmse 2.86 | r2 -1.43 | sharp 1.39
epoch 16 | time used:  0.16s | train_loss 1.622 | valid loss 1.438 | valid acc 0.464 | mae 1.807 | mse 6.635 | rmse 2.58 | r2 -0.97 | sharp 0.00
epoch 17 | time used:  0.16s | train_loss 1.614 | valid loss 1.438 | valid acc 0.464 | mae 1.807 | mse 6.635 | rmse 2.58 | r2 -0.97 | sharp 0.00
epoch 18 | time used:  0.16s | train_loss 1.613 | valid loss 1.438 | valid acc 0.464 | mae 1.807 | mse 6.635 | rmse 2.58 | r2 -0.97 | sharp 0.00
epoch 19 | time used:  0.17s | train_loss 1.613 | valid loss 1.438 | valid acc 0.464 | mae 1.807 | mse 6.635 | rmse 2.58 | r2 -0.97 | sharp 0.00
epoch 20 | time used:  0.16s | train_loss 1.613 | valid loss 1.438 | valid acc 0.464 | mae 1.807 | mse 6.635 | rmse 2.58 | r2 -0.97 | sharp 0.00
saving the model to ./save/2020_300/Attention/checkpoint20.pt
epoch 21 | time used:  0.17s | train_loss 1.613 | valid loss 1.438 | valid acc 0.464 | mae 1.807 | mse 6.635 | rmse 2.58 | r2 -0.97 | sharp 0.00
epoch 22 | time used:  0.17s | train_loss 1.614 | valid loss 1.438 | valid acc 0.464 | mae 1.807 | mse 6.635 | rmse 2.58 | r2 -0.97 | sharp 0.00
epoch 23 | time used:  0.17s | train_loss 1.619 | valid loss 1.438 | valid acc 0.464 | mae 1.807 | mse 6.635 | rmse 2.58 | r2 -0.97 | sharp 0.00
epoch 24 | time used:  0.17s | train_loss 1.613 | valid loss 1.439 | valid acc 0.464 | mae 1.807 | mse 6.635 | rmse 2.58 | r2 -0.97 | sharp 0.00
epoch 25 | time used:  0.17s | train_loss 1.622 | valid loss 1.540 | valid acc 0.366 | mae 2.193 | mse 8.179 | rmse 2.86 | r2 -1.43 | sharp 1.39
epoch 26 | time used:  0.17s | train_loss 1.633 | valid loss 1.822 | valid acc 0.083 | mae 1.747 | mse 3.407 | rmse 1.85 | r2 -0.01 | sharp 1.39
epoch 27 | time used:  0.17s | train_loss 1.655 | valid loss 1.438 | valid acc 0.464 | mae 1.807 | mse 6.635 | rmse 2.58 | r2 -0.97 | sharp 0.00
epoch 28 | time used:  0.17s | train_loss 1.613 | valid loss 1.438 | valid acc 0.464 | mae 1.807 | mse 6.635 | rmse 2.58 | r2 -0.97 | sharp 0.00
epoch 29 | time used:  0.17s | train_loss 1.645 | valid loss 1.863 | valid acc 0.042 | mae 1.735 | mse 4.021 | rmse 2.01 | r2 -0.19 | sharp 1.39
epoch 30 | time used:  0.19s | train_loss 1.665 | valid loss 1.540 | valid acc 0.366 | mae 2.193 | mse 8.179 | rmse 2.86 | r2 -1.43 | sharp 1.39
saving the model to ./save/2020_300/Attention/checkpoint30.pt
epoch 31 | time used:  0.17s | train_loss 1.623 | valid loss 1.540 | valid acc 0.366 | mae 2.193 | mse 8.179 | rmse 2.86 | r2 -1.43 | sharp 1.39
epoch 32 | time used:  0.17s | train_loss 1.628 | valid loss 1.438 | valid acc 0.464 | mae 1.807 | mse 6.635 | rmse 2.58 | r2 -0.97 | sharp 0.00
epoch 33 | time used:  0.17s | train_loss 1.613 | valid loss 1.438 | valid acc 0.464 | mae 1.807 | mse 6.635 | rmse 2.58 | r2 -0.97 | sharp 0.00
epoch 34 | time used:  0.19s | train_loss 1.613 | valid loss 1.438 | valid acc 0.464 | mae 1.807 | mse 6.635 | rmse 2.58 | r2 -0.97 | sharp 0.00
epoch 35 | time used:  0.19s | train_loss 1.604 | valid loss 1.438 | valid acc 0.464 | mae 1.807 | mse 6.635 | rmse 2.58 | r2 -0.97 | sharp 0.00
epoch 36 | time used:  0.19s | train_loss 1.606 | valid loss 1.438 | valid acc 0.464 | mae 1.807 | mse 6.635 | rmse 2.58 | r2 -0.97 | sharp 0.00
epoch 37 | time used:  0.19s | train_loss 1.628 | valid loss 1.822 | valid acc 0.083 | mae 1.747 | mse 3.407 | rmse 1.85 | r2 -0.01 | sharp 1.39
epoch 38 | time used:  0.21s | train_loss 1.760 | valid loss 1.822 | valid acc 0.083 | mae 1.747 | mse 3.407 | rmse 1.85 | r2 -0.01 | sharp 1.39
epoch 39 | time used:  0.17s | train_loss 1.684 | valid loss 1.822 | valid acc 0.083 | mae 1.747 | mse 3.407 | rmse 1.85 | r2 -0.01 | sharp 1.39
epoch 40 | time used:  0.18s | train_loss 1.684 | valid loss 1.822 | valid acc 0.083 | mae 1.747 | mse 3.407 | rmse 1.85 | r2 -0.01 | sharp 1.39
