log/output_300_2020_GRU_gpu1.log
wandb: W&B API key is configured. Use `wandb login --relogin` to force relogin
GPU device ID: 1
newdata/300_2020.npy
0
wandb: wandb version 0.17.9 is available!  To upgrade, please run:
wandb:  $ pip install wandb --upgrade
wandb: Tracking run with wandb version 0.12.17
wandb: Run data is saved locally in /home/qingyi/GPU20/DeepLOB/wandb/run-20240907_160535-gy2aq4up
wandb: Run `wandb offline` to turn off syncing.
wandb: Syncing run GRU
wandb: ⭐️ View project at https://wandb.ai/pqythu/futures300
wandb: 🚀 View run at https://wandb.ai/pqythu/futures300/runs/gy2aq4up
2024-09-07 16:05:46.582200: I tensorflow/core/platform/cpu_feature_guard.cc:193] This TensorFlow binary is optimized with oneAPI Deep Neural Network Library (oneDNN) to use the following CPU instructions in performance-critical operations:  AVX2 FMA
To enable them in other operations, rebuild TensorFlow with the appropriate compiler flags.
Model(
  (rnn): LSTM(10, 64, batch_first=True)
  (fc): Linear(in_features=64, out_features=5, bias=True)
)
number of parameters: 19781
Training start
epoch  1 | time used:  1.05s | train_loss 1.544 | valid loss 1.383 | valid acc 0.570 | mae 1.370 | mse 4.910 | rmse 2.22 | r2 -0.62 | sharp -0.96
epoch  2 | time used:  0.05s | train_loss 1.529 | valid loss 1.383 | valid acc 0.570 | mae 1.370 | mse 4.910 | rmse 2.22 | r2 -0.62 | sharp -0.96
epoch  3 | time used:  0.04s | train_loss 1.509 | valid loss 1.511 | valid acc 0.260 | mae 2.630 | mse 9.950 | rmse 3.15 | r2 -2.28 | sharp 0.00
epoch  4 | time used:  0.05s | train_loss 1.490 | valid loss 1.383 | valid acc 0.570 | mae 1.370 | mse 4.910 | rmse 2.22 | r2 -0.62 | sharp -0.96
epoch  5 | time used:  0.05s | train_loss 1.492 | valid loss 1.383 | valid acc 0.570 | mae 1.370 | mse 4.910 | rmse 2.22 | r2 -0.62 | sharp -0.96
epoch  6 | time used:  0.05s | train_loss 1.449 | valid loss 1.516 | valid acc 0.260 | mae 2.630 | mse 9.950 | rmse 3.15 | r2 -2.28 | sharp 0.00
epoch  7 | time used:  0.05s | train_loss 1.513 | valid loss 1.517 | valid acc 0.260 | mae 2.630 | mse 9.950 | rmse 3.15 | r2 -2.28 | sharp 0.00
epoch  8 | time used:  0.05s | train_loss 1.535 | valid loss 1.383 | valid acc 0.570 | mae 1.370 | mse 4.910 | rmse 2.22 | r2 -0.62 | sharp -0.96
epoch  9 | time used:  0.04s | train_loss 1.507 | valid loss 1.394 | valid acc 0.570 | mae 1.370 | mse 4.910 | rmse 2.22 | r2 -0.62 | sharp -0.96
epoch 10 | time used:  0.04s | train_loss 1.482 | valid loss 1.382 | valid acc 0.570 | mae 1.370 | mse 4.910 | rmse 2.22 | r2 -0.62 | sharp -0.96
saving the model to ./save/2020_300/GRU/checkpoint10.pt
epoch 11 | time used:  0.05s | train_loss 1.531 | valid loss 1.517 | valid acc 0.260 | mae 2.630 | mse 9.950 | rmse 3.15 | r2 -2.28 | sharp 0.00
epoch 12 | time used:  0.05s | train_loss 1.479 | valid loss 1.383 | valid acc 0.570 | mae 1.370 | mse 4.910 | rmse 2.22 | r2 -0.62 | sharp -0.96
epoch 13 | time used:  0.05s | train_loss 1.473 | valid loss 1.383 | valid acc 0.570 | mae 1.370 | mse 4.910 | rmse 2.22 | r2 -0.62 | sharp -0.96
epoch 14 | time used:  0.05s | train_loss 1.472 | valid loss 1.383 | valid acc 0.570 | mae 1.370 | mse 4.910 | rmse 2.22 | r2 -0.62 | sharp -0.96
epoch 15 | time used:  0.05s | train_loss 1.474 | valid loss 1.381 | valid acc 0.570 | mae 1.370 | mse 4.910 | rmse 2.22 | r2 -0.62 | sharp -0.96
epoch 16 | time used:  0.05s | train_loss 1.452 | valid loss 1.382 | valid acc 0.570 | mae 1.370 | mse 4.910 | rmse 2.22 | r2 -0.62 | sharp -0.96
epoch 17 | time used:  0.05s | train_loss 1.453 | valid loss 1.516 | valid acc 0.260 | mae 2.630 | mse 9.950 | rmse 3.15 | r2 -2.28 | sharp 0.00
epoch 18 | time used:  0.05s | train_loss 1.508 | valid loss 1.517 | valid acc 0.260 | mae 2.630 | mse 9.950 | rmse 3.15 | r2 -2.28 | sharp 0.00
epoch 19 | time used:  0.05s | train_loss 1.496 | valid loss 1.516 | valid acc 0.260 | mae 2.630 | mse 9.950 | rmse 3.15 | r2 -2.28 | sharp 0.00
epoch 20 | time used:  0.04s | train_loss 1.525 | valid loss 1.516 | valid acc 0.260 | mae 2.630 | mse 9.950 | rmse 3.15 | r2 -2.28 | sharp 0.00
saving the model to ./save/2020_300/GRU/checkpoint20.pt
epoch 21 | time used:  0.04s | train_loss 1.511 | valid loss 1.517 | valid acc 0.260 | mae 2.630 | mse 9.950 | rmse 3.15 | r2 -2.28 | sharp 0.00
epoch 22 | time used:  0.04s | train_loss 1.482 | valid loss 1.383 | valid acc 0.570 | mae 1.370 | mse 4.910 | rmse 2.22 | r2 -0.62 | sharp -0.96
epoch 23 | time used:  0.04s | train_loss 1.508 | valid loss 1.383 | valid acc 0.570 | mae 1.370 | mse 4.910 | rmse 2.22 | r2 -0.62 | sharp -0.96
epoch 24 | time used:  0.04s | train_loss 1.451 | valid loss 1.383 | valid acc 0.570 | mae 1.370 | mse 4.910 | rmse 2.22 | r2 -0.62 | sharp -0.96
epoch 25 | time used:  0.04s | train_loss 1.478 | valid loss 1.383 | valid acc 0.570 | mae 1.370 | mse 4.910 | rmse 2.22 | r2 -0.62 | sharp -0.96
epoch 26 | time used:  0.04s | train_loss 1.484 | valid loss 1.384 | valid acc 0.570 | mae 1.370 | mse 4.910 | rmse 2.22 | r2 -0.62 | sharp -0.96
epoch 27 | time used:  0.04s | train_loss 1.474 | valid loss 1.383 | valid acc 0.570 | mae 1.370 | mse 4.910 | rmse 2.22 | r2 -0.62 | sharp -0.96
epoch 28 | time used:  0.05s | train_loss 1.499 | valid loss 1.384 | valid acc 0.570 | mae 1.370 | mse 4.910 | rmse 2.22 | r2 -0.62 | sharp -0.96
epoch 29 | time used:  0.04s | train_loss 1.464 | valid loss 1.383 | valid acc 0.570 | mae 1.370 | mse 4.910 | rmse 2.22 | r2 -0.62 | sharp -0.96
epoch 30 | time used:  0.04s | train_loss 1.497 | valid loss 1.383 | valid acc 0.570 | mae 1.370 | mse 4.910 | rmse 2.22 | r2 -0.62 | sharp -0.96
saving the model to ./save/2020_300/GRU/checkpoint30.pt
epoch 31 | time used:  0.04s | train_loss 1.496 | valid loss 1.516 | valid acc 0.260 | mae 2.630 | mse 9.950 | rmse 3.15 | r2 -2.28 | sharp 0.00
epoch 32 | time used:  0.05s | train_loss 1.509 | valid loss 1.516 | valid acc 0.260 | mae 2.630 | mse 9.950 | rmse 3.15 | r2 -2.28 | sharp 0.00
epoch 33 | time used:  0.04s | train_loss 1.514 | valid loss 1.517 | valid acc 0.260 | mae 2.630 | mse 9.950 | rmse 3.15 | r2 -2.28 | sharp 0.00
epoch 34 | time used:  0.04s | train_loss 1.497 | valid loss 1.504 | valid acc 0.260 | mae 2.630 | mse 9.950 | rmse 3.15 | r2 -2.28 | sharp 0.00
epoch 35 | time used:  0.04s | train_loss 1.494 | valid loss 1.384 | valid acc 0.570 | mae 1.370 | mse 4.910 | rmse 2.22 | r2 -0.62 | sharp -0.96
epoch 36 | time used:  0.04s | train_loss 1.473 | valid loss 1.383 | valid acc 0.570 | mae 1.370 | mse 4.910 | rmse 2.22 | r2 -0.62 | sharp -0.96
epoch 37 | time used:  0.05s | train_loss 1.488 | valid loss 1.383 | valid acc 0.570 | mae 1.370 | mse 4.910 | rmse 2.22 | r2 -0.62 | sharp -0.96
epoch 38 | time used:  0.04s | train_loss 1.475 | valid loss 1.383 | valid acc 0.570 | mae 1.370 | mse 4.910 | rmse 2.22 | r2 -0.62 | sharp -0.96
epoch 39 | time used:  0.04s | train_loss 1.469 | valid loss 1.383 | valid acc 0.570 | mae 1.370 | mse 4.910 | rmse 2.22 | r2 -0.62 | sharp -0.96
epoch 40 | time used:  0.04s | train_loss 1.490 | valid loss 1.374 | valid acc 0.570 | mae 1.370 | mse 4.910 | rmse 2.22 | r2 -0.62 | sharp -0.96
saving the model to ./save/2020_300/GRU/checkpoint40.pt
epoch 41 | time used:  0.04s | train_loss 1.474 | valid loss 1.383 | valid acc 0.570 | mae 1.370 | mse 4.910 | rmse 2.22 | r2 -0.62 | sharp -0.96
epoch 42 | time used:  0.04s | train_loss 1.459 | valid loss 1.384 | valid acc 0.570 | mae 1.370 | mse 4.910 | rmse 2.22 | r2 -0.62 | sharp -0.96
epoch 43 | time used:  0.05s | train_loss 1.456 | valid loss 1.383 | valid acc 0.570 | mae 1.370 | mse 4.910 | rmse 2.22 | r2 -0.62 | sharp -0.96
epoch 44 | time used:  0.06s | train_loss 1.463 | valid loss 1.383 | valid acc 0.570 | mae 1.370 | mse 4.910 | rmse 2.22 | r2 -0.62 | sharp -0.96
epoch 45 | time used:  0.06s | train_loss 1.473 | valid loss 1.383 | valid acc 0.570 | mae 1.370 | mse 4.910 | rmse 2.22 | r2 -0.62 | sharp -0.96
epoch 46 | time used:  0.06s | train_loss 1.513 | valid loss 1.396 | valid acc 0.570 | mae 1.370 | mse 4.910 | rmse 2.22 | r2 -0.62 | sharp -0.96
